<?xml version="1.0" encoding="UTF-8"?>
<testng-results skipped="0" failed="3" ignored="0" total="4" passed="1">
  <reporter-output>
  </reporter-output>
  <suite name="Default suite" duration-ms="53867" started-at="2019-07-22T15:03:34Z" finished-at="2019-07-22T15:04:28Z">
    <groups>
    </groups>
    <test name="Default test" duration-ms="53867" started-at="2019-07-22T15:03:34Z" finished-at="2019-07-22T15:04:28Z">
      <class name="com.Test2_Parametrization">
        <test-method status="PASS" signature="validCredentials(java.lang.String, java.lang.String)[pri:0, instance:com.Test2_Parametrization@3532ec19]" name="validCredentials" duration-ms="13028" started-at="2019-07-22T15:03:34Z" data-provider="getData" finished-at="2019-07-22T15:03:47Z">
          <params>
            <param index="0">
              <value>
                <![CDATA[mngr208757]]>
              </value>
            </param>
            <param index="1">
              <value>
                <![CDATA[qYgAvYd]]>
              </value>
            </param>
          </params>
          <reporter-output>
          </reporter-output>
        </test-method> <!-- validCredentials -->
        <test-method status="FAIL" signature="validCredentials(java.lang.String, java.lang.String)[pri:0, instance:com.Test2_Parametrization@3532ec19]" name="validCredentials" duration-ms="8690" started-at="2019-07-22T15:03:47Z" data-provider="getData" finished-at="2019-07-22T15:03:56Z">
          <params>
            <param index="0">
              <value>
                <![CDATA[mngr208757]]>
              </value>
            </param>
            <param index="1">
              <value>
                <![CDATA[pass]]>
              </value>
            </param>
          </params>
          <exception class="java.lang.AssertionError">
            <message>
              <![CDATA[expected [XXXUser or Password is not valid] but found [User or Password is not valid]]]>
            </message>
            <full-stacktrace>
              <![CDATA[java.lang.AssertionError: expected [XXXUser or Password is not valid] but found [User or Password is not valid]
at org.testng.Assert.fail(Assert.java:96)
at org.testng.Assert.failNotEquals(Assert.java:776)
at org.testng.Assert.assertEqualsImpl(Assert.java:137)
at org.testng.Assert.assertEquals(Assert.java:118)
at org.testng.Assert.assertEquals(Assert.java:453)
at org.testng.Assert.assertEquals(Assert.java:463)
at com.Test2_Parametrization.validCredentials(Test2_Parametrization.java:39)
at sun.reflect.NativeMethodAccessorImpl.invoke0(Native Method)
at sun.reflect.NativeMethodAccessorImpl.invoke(Unknown Source)
at sun.reflect.DelegatingMethodAccessorImpl.invoke(Unknown Source)
at java.lang.reflect.Method.invoke(Unknown Source)
at org.testng.internal.MethodInvocationHelper.invokeMethod(MethodInvocationHelper.java:124)
at org.testng.internal.Invoker.invokeMethod(Invoker.java:583)
at org.testng.internal.Invoker.invokeTestMethod(Invoker.java:719)
at org.testng.internal.Invoker.invokeTestMethods(Invoker.java:989)
at org.testng.internal.TestMethodWorker.invokeTestMethods(TestMethodWorker.java:125)
at org.testng.internal.TestMethodWorker.run(TestMethodWorker.java:109)
at org.testng.TestRunner.privateRun(TestRunner.java:648)
at org.testng.TestRunner.run(TestRunner.java:505)
at org.testng.SuiteRunner.runTest(SuiteRunner.java:455)
at org.testng.SuiteRunner.runSequentially(SuiteRunner.java:450)
at org.testng.SuiteRunner.privateRun(SuiteRunner.java:415)
at org.testng.SuiteRunner.run(SuiteRunner.java:364)
at org.testng.SuiteRunnerWorker.runSuite(SuiteRunnerWorker.java:52)
at org.testng.SuiteRunnerWorker.run(SuiteRunnerWorker.java:84)
at org.testng.TestNG.runSuitesSequentially(TestNG.java:1208)
at org.testng.TestNG.runSuitesLocally(TestNG.java:1137)
at org.testng.TestNG.runSuites(TestNG.java:1049)
at org.testng.TestNG.run(TestNG.java:1017)
at org.testng.remote.AbstractRemoteTestNG.run(AbstractRemoteTestNG.java:115)
at org.testng.remote.RemoteTestNG.initAndRun(RemoteTestNG.java:251)
at org.testng.remote.RemoteTestNG.main(RemoteTestNG.java:77)
]]>
            </full-stacktrace>
          </exception> <!-- java.lang.AssertionError -->
          <reporter-output>
          </reporter-output>
        </test-method> <!-- validCredentials -->
        <test-method status="FAIL" signature="validCredentials(java.lang.String, java.lang.String)[pri:0, instance:com.Test2_Parametrization@3532ec19]" name="validCredentials" duration-ms="15869" started-at="2019-07-22T15:03:56Z" data-provider="getData" finished-at="2019-07-22T15:04:12Z">
          <params>
            <param index="0">
              <value>
                <![CDATA[uname3]]>
              </value>
            </param>
            <param index="1">
              <value>
                <![CDATA[qYgAvYd]]>
              </value>
            </param>
          </params>
          <exception class="java.lang.AssertionError">
            <message>
              <![CDATA[expected [XXXUser or Password is not valid] but found [User or Password is not valid]]]>
            </message>
            <full-stacktrace>
              <![CDATA[java.lang.AssertionError: expected [XXXUser or Password is not valid] but found [User or Password is not valid]
at org.testng.Assert.fail(Assert.java:96)
at org.testng.Assert.failNotEquals(Assert.java:776)
at org.testng.Assert.assertEqualsImpl(Assert.java:137)
at org.testng.Assert.assertEquals(Assert.java:118)
at org.testng.Assert.assertEquals(Assert.java:453)
at org.testng.Assert.assertEquals(Assert.java:463)
at com.Test2_Parametrization.validCredentials(Test2_Parametrization.java:39)
at sun.reflect.NativeMethodAccessorImpl.invoke0(Native Method)
at sun.reflect.NativeMethodAccessorImpl.invoke(Unknown Source)
at sun.reflect.DelegatingMethodAccessorImpl.invoke(Unknown Source)
at java.lang.reflect.Method.invoke(Unknown Source)
at org.testng.internal.MethodInvocationHelper.invokeMethod(MethodInvocationHelper.java:124)
at org.testng.internal.Invoker.invokeMethod(Invoker.java:583)
at org.testng.internal.Invoker.invokeTestMethod(Invoker.java:719)
at org.testng.internal.Invoker.invokeTestMethods(Invoker.java:989)
at org.testng.internal.TestMethodWorker.invokeTestMethods(TestMethodWorker.java:125)
at org.testng.internal.TestMethodWorker.run(TestMethodWorker.java:109)
at org.testng.TestRunner.privateRun(TestRunner.java:648)
at org.testng.TestRunner.run(TestRunner.java:505)
at org.testng.SuiteRunner.runTest(SuiteRunner.java:455)
at org.testng.SuiteRunner.runSequentially(SuiteRunner.java:450)
at org.testng.SuiteRunner.privateRun(SuiteRunner.java:415)
at org.testng.SuiteRunner.run(SuiteRunner.java:364)
at org.testng.SuiteRunnerWorker.runSuite(SuiteRunnerWorker.java:52)
at org.testng.SuiteRunnerWorker.run(SuiteRunnerWorker.java:84)
at org.testng.TestNG.runSuitesSequentially(TestNG.java:1208)
at org.testng.TestNG.runSuitesLocally(TestNG.java:1137)
at org.testng.TestNG.runSuites(TestNG.java:1049)
at org.testng.TestNG.run(TestNG.java:1017)
at org.testng.remote.AbstractRemoteTestNG.run(AbstractRemoteTestNG.java:115)
at org.testng.remote.RemoteTestNG.initAndRun(RemoteTestNG.java:251)
at org.testng.remote.RemoteTestNG.main(RemoteTestNG.java:77)
]]>
            </full-stacktrace>
          </exception> <!-- java.lang.AssertionError -->
          <reporter-output>
          </reporter-output>
        </test-method> <!-- validCredentials -->
        <test-method status="FAIL" signature="validCredentials(java.lang.String, java.lang.String)[pri:0, instance:com.Test2_Parametrization@3532ec19]" name="validCredentials" duration-ms="16046" started-at="2019-07-22T15:04:12Z" data-provider="getData" finished-at="2019-07-22T15:04:28Z">
          <params>
            <param index="0">
              <value>
                <![CDATA[uname4]]>
              </value>
            </param>
            <param index="1">
              <value>
                <![CDATA[pass]]>
              </value>
            </param>
          </params>
          <exception class="java.lang.AssertionError">
            <message>
              <![CDATA[expected [XXXUser or Password is not valid] but found [User or Password is not valid]]]>
            </message>
            <full-stacktrace>
              <![CDATA[java.lang.AssertionError: expected [XXXUser or Password is not valid] but found [User or Password is not valid]
at org.testng.Assert.fail(Assert.java:96)
at org.testng.Assert.failNotEquals(Assert.java:776)
at org.testng.Assert.assertEqualsImpl(Assert.java:137)
at org.testng.Assert.assertEquals(Assert.java:118)
at org.testng.Assert.assertEquals(Assert.java:453)
at org.testng.Assert.assertEquals(Assert.java:463)
at com.Test2_Parametrization.validCredentials(Test2_Parametrization.java:39)
at sun.reflect.NativeMethodAccessorImpl.invoke0(Native Method)
at sun.reflect.NativeMethodAccessorImpl.invoke(Unknown Source)
at sun.reflect.DelegatingMethodAccessorImpl.invoke(Unknown Source)
at java.lang.reflect.Method.invoke(Unknown Source)
at org.testng.internal.MethodInvocationHelper.invokeMethod(MethodInvocationHelper.java:124)
at org.testng.internal.Invoker.invokeMethod(Invoker.java:583)
at org.testng.internal.Invoker.invokeTestMethod(Invoker.java:719)
at org.testng.internal.Invoker.invokeTestMethods(Invoker.java:989)
at org.testng.internal.TestMethodWorker.invokeTestMethods(TestMethodWorker.java:125)
at org.testng.internal.TestMethodWorker.run(TestMethodWorker.java:109)
at org.testng.TestRunner.privateRun(TestRunner.java:648)
at org.testng.TestRunner.run(TestRunner.java:505)
at org.testng.SuiteRunner.runTest(SuiteRunner.java:455)
at org.testng.SuiteRunner.runSequentially(SuiteRunner.java:450)
at org.testng.SuiteRunner.privateRun(SuiteRunner.java:415)
at org.testng.SuiteRunner.run(SuiteRunner.java:364)
at org.testng.SuiteRunnerWorker.runSuite(SuiteRunnerWorker.java:52)
at org.testng.SuiteRunnerWorker.run(SuiteRunnerWorker.java:84)
at org.testng.TestNG.runSuitesSequentially(TestNG.java:1208)
at org.testng.TestNG.runSuitesLocally(TestNG.java:1137)
at org.testng.TestNG.runSuites(TestNG.java:1049)
at org.testng.TestNG.run(TestNG.java:1017)
at org.testng.remote.AbstractRemoteTestNG.run(AbstractRemoteTestNG.java:115)
at org.testng.remote.RemoteTestNG.initAndRun(RemoteTestNG.java:251)
at org.testng.remote.RemoteTestNG.main(RemoteTestNG.java:77)
]]>
            </full-stacktrace>
          </exception> <!-- java.lang.AssertionError -->
          <reporter-output>
          </reporter-output>
        </test-method> <!-- validCredentials -->
        <test-method status="PASS" signature="tearDown()[pri:0, instance:com.Test2_Parametrization@3532ec19]" name="tearDown" is-config="true" duration-ms="152" started-at="2019-07-22T15:04:28Z" finished-at="2019-07-22T15:04:28Z">
          <reporter-output>
          </reporter-output>
        </test-method> <!-- tearDown -->
      </class> <!-- com.Test2_Parametrization -->
    </test> <!-- Default test -->
  </suite> <!-- Default suite -->
</testng-results>
